2024-11-13 04:04:01.647 | INFO     | app.modules.plant_heatmap.routers:query_result:35 - ===== Query plant heatmap =====
2024-11-13 04:04:01.647 | INFO     | app.modules.plant_heatmap.routers:query_result:36 - Client IP: 172.23.0.1
2024-11-13 04:04:01.651 | INFO     | app.modules.plant_heatmap.routers:query_result:37 - User-Agent: Mozilla/5.0 (X11; Linux x86_64) AppleWebKit/537.36 (KHTML, like Gecko) Chrome/117.0.0.0 Safari/537.36
2024-11-13 04:04:01.697 | ERROR    | app.modules.plant_heatmap.services:get_image_results:85 - Error: Traceback (most recent call last):
  File "/workspace/refactor/vss_controller/app/modules/plant_heatmap/services.py", line 41, in get_image_results
    date_object = datetime.strptime(datetime_str, "%Y-%m-%d")
  File "/usr/lib/python3.10/_strptime.py", line 568, in _strptime_datetime
    tt, fraction, gmtoff_fraction = _strptime(data_string, format)
  File "/usr/lib/python3.10/_strptime.py", line 349, in _strptime
    raise ValueError("time data %r does not match format %r" %
ValueError: time data 'string' does not match format '%Y-%m-%d'

2024-11-13 04:04:01.719 | ERROR    | app.modules.plant_heatmap.services:query_result:112 - Traceback (most recent call last):
  File "/workspace/refactor/vss_controller/app/modules/plant_heatmap/services.py", line 41, in get_image_results
    date_object = datetime.strptime(datetime_str, "%Y-%m-%d")
  File "/usr/lib/python3.10/_strptime.py", line 568, in _strptime_datetime
    tt, fraction, gmtoff_fraction = _strptime(data_string, format)
  File "/usr/lib/python3.10/_strptime.py", line 349, in _strptime
    raise ValueError("time data %r does not match format %r" %
ValueError: time data 'string' does not match format '%Y-%m-%d'

During handling of the above exception, another exception occurred:

Traceback (most recent call last):
  File "/workspace/refactor/vss_controller/app/modules/plant_heatmap/services.py", line 104, in query_result
    status_code = self.get_image_results(data)
  File "/usr/lib/python3.10/contextlib.py", line 79, in inner
    return func(*args, **kwds)
  File "/workspace/refactor/vss_controller/app/modules/plant_heatmap/services.py", line 86, in get_image_results
    status_code = StatusCode.UNKNOWN_ERROR
NameError: name 'StatusCode' is not defined

2024-11-13 04:27:15.140 | INFO     | app.modules.plant_heatmap.routers:query_result:35 - ===== Query plant heatmap =====
2024-11-13 04:27:15.140 | INFO     | app.modules.plant_heatmap.routers:query_result:36 - Client IP: 172.23.0.1
2024-11-13 04:27:15.146 | INFO     | app.modules.plant_heatmap.routers:query_result:37 - User-Agent: Mozilla/5.0 (X11; Linux x86_64) AppleWebKit/537.36 (KHTML, like Gecko) Chrome/117.0.0.0 Safari/537.36
2024-11-13 04:27:15.180 | ERROR    | app.modules.plant_heatmap.services:get_image_results:45 - Traceback (most recent call last):
  File "/workspace/refactor/vss_controller/app/modules/plant_heatmap/services.py", line 42, in get_image_results
    date_object = datetime.strptime(datetime_str, "%Y-%m-%d")
  File "/usr/lib/python3.10/_strptime.py", line 568, in _strptime_datetime
    tt, fraction, gmtoff_fraction = _strptime(data_string, format)
  File "/usr/lib/python3.10/_strptime.py", line 349, in _strptime
    raise ValueError("time data %r does not match format %r" %
ValueError: time data 'string' does not match format '%Y-%m-%d'

2024-11-13 04:27:15.191 | ERROR    | app.modules.plant_heatmap.services:get_image_results:91 - Error: Traceback (most recent call last):
  File "/workspace/refactor/vss_controller/app/modules/plant_heatmap/services.py", line 42, in get_image_results
    date_object = datetime.strptime(datetime_str, "%Y-%m-%d")
  File "/usr/lib/python3.10/_strptime.py", line 568, in _strptime_datetime
    tt, fraction, gmtoff_fraction = _strptime(data_string, format)
  File "/usr/lib/python3.10/_strptime.py", line 349, in _strptime
    raise ValueError("time data %r does not match format %r" %
ValueError: time data 'string' does not match format '%Y-%m-%d'

During handling of the above exception, another exception occurred:

Traceback (most recent call last):
  File "/workspace/refactor/vss_controller/app/modules/plant_heatmap/services.py", line 46, in get_image_results
    status_code = StatusCode.NOT_SUCCESS
NameError: name 'StatusCode' is not defined

2024-11-13 04:27:15.197 | ERROR    | app.modules.plant_heatmap.services:query_result:118 - Traceback (most recent call last):
  File "/workspace/refactor/vss_controller/app/modules/plant_heatmap/services.py", line 42, in get_image_results
    date_object = datetime.strptime(datetime_str, "%Y-%m-%d")
  File "/usr/lib/python3.10/_strptime.py", line 568, in _strptime_datetime
    tt, fraction, gmtoff_fraction = _strptime(data_string, format)
  File "/usr/lib/python3.10/_strptime.py", line 349, in _strptime
    raise ValueError("time data %r does not match format %r" %
ValueError: time data 'string' does not match format '%Y-%m-%d'

During handling of the above exception, another exception occurred:

Traceback (most recent call last):
  File "/workspace/refactor/vss_controller/app/modules/plant_heatmap/services.py", line 46, in get_image_results
    status_code = StatusCode.NOT_SUCCESS
NameError: name 'StatusCode' is not defined

During handling of the above exception, another exception occurred:

Traceback (most recent call last):
  File "/workspace/refactor/vss_controller/app/modules/plant_heatmap/services.py", line 110, in query_result
    status_code = self.get_image_results(data)
  File "/usr/lib/python3.10/contextlib.py", line 79, in inner
    return func(*args, **kwds)
  File "/workspace/refactor/vss_controller/app/modules/plant_heatmap/services.py", line 92, in get_image_results
    status_code = StatusCode.UNKNOWN_ERROR
NameError: name 'StatusCode' is not defined

2024-11-13 04:29:08.645 | INFO     | app.modules.plant_heatmap.routers:query_result:35 - ===== Query plant heatmap =====
2024-11-13 04:29:08.646 | INFO     | app.modules.plant_heatmap.routers:query_result:36 - Client IP: 172.23.0.1
2024-11-13 04:29:08.650 | INFO     | app.modules.plant_heatmap.routers:query_result:37 - User-Agent: Mozilla/5.0 (X11; Linux x86_64) AppleWebKit/537.36 (KHTML, like Gecko) Chrome/117.0.0.0 Safari/537.36
2024-11-13 04:29:08.674 | ERROR    | app.modules.plant_heatmap.services:get_image_results:46 - Traceback (most recent call last):
  File "/workspace/refactor/vss_controller/app/modules/plant_heatmap/services.py", line 43, in get_image_results
    date_object = datetime.strptime(datetime_str, "%Y-%m-%d")
  File "/usr/lib/python3.10/_strptime.py", line 568, in _strptime_datetime
    tt, fraction, gmtoff_fraction = _strptime(data_string, format)
  File "/usr/lib/python3.10/_strptime.py", line 349, in _strptime
    raise ValueError("time data %r does not match format %r" %
ValueError: time data 'string' does not match format '%Y-%m-%d'

2024-11-13 04:29:08.678 | ERROR    | app.modules.plant_heatmap.services:query_result:119 - Traceback (most recent call last):
  File "/workspace/refactor/vss_controller/app/modules/plant_heatmap/services.py", line 112, in query_result
    status_code.value["content"]["detail"]["header"] = {
KeyError: 'detail'

2024-11-13 04:31:29.085 | INFO     | app.modules.plant_heatmap.routers:query_result:35 - ===== Query plant heatmap =====
2024-11-13 04:31:29.085 | INFO     | app.modules.plant_heatmap.routers:query_result:36 - Client IP: 172.23.0.1
2024-11-13 04:31:29.089 | INFO     | app.modules.plant_heatmap.routers:query_result:37 - User-Agent: Mozilla/5.0 (X11; Linux x86_64) AppleWebKit/537.36 (KHTML, like Gecko) Chrome/117.0.0.0 Safari/537.36
2024-11-13 04:31:29.114 | ERROR    | app.modules.plant_heatmap.services:get_image_results:46 - Traceback (most recent call last):
  File "/workspace/refactor/vss_controller/app/modules/plant_heatmap/services.py", line 43, in get_image_results
    date_object = datetime.strptime(datetime_str, "%Y-%m-%d")
  File "/usr/lib/python3.10/_strptime.py", line 568, in _strptime_datetime
    tt, fraction, gmtoff_fraction = _strptime(data_string, format)
  File "/usr/lib/python3.10/_strptime.py", line 349, in _strptime
    raise ValueError("time data %r does not match format %r" %
ValueError: time data 'string' does not match format '%Y-%m-%d'

2024-11-13 04:31:29.119 | ERROR    | app.modules.plant_heatmap.services:query_result:120 - Traceback (most recent call last):
  File "/workspace/refactor/vss_controller/app/modules/plant_heatmap/services.py", line 112, in query_result
    if status_code["http_code"] == 200:
TypeError: 'StatusCode' object is not subscriptable

2024-11-13 04:31:46.987 | INFO     | app.modules.plant_heatmap.routers:query_result:35 - ===== Query plant heatmap =====
2024-11-13 04:31:46.987 | INFO     | app.modules.plant_heatmap.routers:query_result:36 - Client IP: 172.23.0.1
2024-11-13 04:31:46.991 | INFO     | app.modules.plant_heatmap.routers:query_result:37 - User-Agent: Mozilla/5.0 (X11; Linux x86_64) AppleWebKit/537.36 (KHTML, like Gecko) Chrome/117.0.0.0 Safari/537.36
2024-11-13 04:31:47.018 | ERROR    | app.modules.plant_heatmap.services:get_image_results:46 - Traceback (most recent call last):
  File "/workspace/refactor/vss_controller/app/modules/plant_heatmap/services.py", line 43, in get_image_results
    date_object = datetime.strptime(datetime_str, "%Y-%m-%d")
  File "/usr/lib/python3.10/_strptime.py", line 568, in _strptime_datetime
    tt, fraction, gmtoff_fraction = _strptime(data_string, format)
  File "/usr/lib/python3.10/_strptime.py", line 349, in _strptime
    raise ValueError("time data %r does not match format %r" %
ValueError: time data 'string' does not match format '%Y-%m-%d'

2024-11-13 04:33:17.763 | INFO     | app.modules.plant_heatmap.routers:query_result:35 - ===== Query plant heatmap =====
2024-11-13 04:33:17.763 | INFO     | app.modules.plant_heatmap.routers:query_result:36 - Client IP: 172.23.0.1
2024-11-13 04:33:17.769 | INFO     | app.modules.plant_heatmap.routers:query_result:37 - User-Agent: Mozilla/5.0 (X11; Linux x86_64) AppleWebKit/537.36 (KHTML, like Gecko) Chrome/117.0.0.0 Safari/537.36
2024-11-13 04:33:17.787 | ERROR    | app.modules.plant_heatmap.services:get_image_results:47 - Traceback (most recent call last):
  File "/workspace/refactor/vss_controller/app/modules/plant_heatmap/services.py", line 44, in get_image_results
    date_object = datetime.strptime(datetime_str, "%Y-%m-%d")
  File "/usr/lib/python3.10/_strptime.py", line 568, in _strptime_datetime
    tt, fraction, gmtoff_fraction = _strptime(data_string, format)
  File "/usr/lib/python3.10/_strptime.py", line 349, in _strptime
    raise ValueError("time data %r does not match format %r" %
ValueError: time data 'string' does not match format '%Y-%m-%d'

